Workbook

Sheet urunler
A1: UrunKodu | B1: Kategori | C1: UrunAciklamasi | D1: UrunAciklamasiEn | E1: BirimFiyat | F1: MaliyetFiyati | G1: EklenmeTarihi | H1: FiyatTL | I1: FiyatUSD | J1: FiyatEUR
A2: LT-G0200 | B2: Belli Değil | C2: Laboratuar Etüvü, 30 litre kapasiteli, ortam sıcaklığı ile 200°C ±2°C arasında, PID dijital kontrol sistemli, Güvenlik termostatlı, Dahili Hava Sirkülasyon Sistemli, İç Yüzey Yapısı : Paslanmaz Çelik İç Hazne, Dış Yüzey Yapısı : Elektrostatik Toz Boyalı Çelik, 2 adet ayarlanabilir raf ile birlikte verilmektedir. 220 V, 50-60 Hz, 1 ph | D2: Laboratory oven, 30 L capacity, ambient to 200°C ±2°C, PID digital control system, equipped of a dual safety thermostat, fan circulated, stainless steel interior, electrostatic painted exterior, 2 adjustable shelves. 220 V, 50-60 Hz, 1 ph | E2: =H2*1.8*1.4 -> 0 | F2: 0 | G2: 2025-09-04 15:23:18.020 | H2: =K2*1.8*1.4 -> 0 | I2: 870 | J2: 810
A3: LT-G0201 | B3: Belli Değil | C3: Laboratuar Etüvü, 50 litre kapasiteli, ortam sıcaklığı ile 200°C ±2°C arasında, PID dijital kontrol sistemli, Güvenlik termostatlı, Dahili Hava Sirkülasyon Sistemli, İç Yüzey Yapısı : Paslanmaz Çelik İç Hazne, Dış Yüzey Yapısı : Elektrostatik Toz Boyalı Çelik, 2 adet ayarlanabilir raf ile birlikte verilmektedir. 220 V, 50-60 Hz, 1 ph | D3: Laboratory oven, 50 L capacity, ambient to 200°C ±2°C, PID digital control system, equipped of a dual safety thermostat, fan circulated, stainless steel interior, electrostatic painted exterior, 2 adjustable shelves. 220 V, 50-60 Hz, 1 ph | E3: =H3*1.8*1.4 -> 0 | F3: 33810 | G3: 2025-09-04 15:23:18.021 | H3: =K3*1.8*1.4 -> 0 | I3: 930 | J3: 861
A4: LT-G0202 | B4: Belli Değil | C4: Laboratuar Etüvü, 120 litre kapasiteli, ortam sıcaklığı ile 200°C ±2°C arasında, PID dijital kontrol sistemli, Güvenlik termostatlı, Dahili Hava Sirkülasyon Sistemli, İç Yüzey Yapısı : Paslanmaz Çelik İç Hazne, Dış Yüzey Yapısı : Elektrostatik Toz Boyalı Çelik, 2 adet ayarlanabilir raf ile birlikte verilmektedir. 220 V, 50-60 Hz, 1 ph | D4: Laboratory oven, 120 L capacity, ambient to 200°C ±2°C, PID digital control system, equipped of a dual safety thermostat, fan circulated, stainless steel interior, electrostatic painted exterior, 2 adjustable shelves. 220 V, 50-60 Hz, 1 ph | E4: =H4*1.8*1.4 -> 0 | F4: ='[1]120 LT ETÜV'!$L$2 -> 18284.5 | G4: 2025-09-04 15:23:18.022 | H4: =K4*1.8*1.4 -> 0 | I4: 1020 | J4: 945
A5: LT-G0202/H | B5: Belli Değil | C5: Laboratuar Etüvü, 120 litre kapasiteli, ortam sıcaklığı ile 300°C ±2°C arasında, PID dijital kontrol sistemli, Güvenlik termostatlı, Dahili Hava Sirkülasyon Sistemli, İç Yüzey Yapısı : Paslanmaz Çelik İç Hazne, Dış Yüzey Yapısı : Elektrostatik Toz Boyalı Çelik, 2 adet ayarlanabilir raf ile birlikte verilmektedir. 220 V, 50-60 Hz, 1 ph | D5: Laboratory oven, 120 L capacity, ambient to 300°C ±2°C, PID digital control system, equipped of a dual safety thermostat, fan circulated, stainless steel interior, electrostatic painted exterior, 2 adjustable shelves. 220 V, 50-60 Hz, 1 ph | E5: =H5*1.8*1.4 -> 0 | F5: ='[1]120 LT ETÜV'!$L$2 -> 18284.5 | G5: 2025-09-04 15:23:18.023 | H5: =K5*1.8*1.4 -> 0 | I5: 1200 | J5: 1112
A6: LT-G0203 | B6: Belli Değil | C6: Laboratuar Etüvü, 250 litre kapasiteli, ortam sıcaklığı ile 200°C ±2°C arasında, PID dijital kontrol sistemli, Güvenlik termostatlı, Dahili Hava Sirkülasyon Sistemli, İç Yüzey Yapısı : Paslanmaz Çelik İç Hazne, Dış Yüzey Yapısı : Elektrostatik Toz Boyalı Çelik, 3 adet ayarlanabilir raf ile birlikte verilmektedir. 220 V, 50-60 Hz, 1 ph | D6: Laboratory oven, 250 L capacity, ambient to 200°C ±2°C, PID digital control system, equipped of a dual safety thermostat, fan circulated, stainless steel interior, electrostatic painted exterior, 3 adjustable shelves. 220 V, 50-60 Hz, 1 ph | E6: =H6*1.8*1.4 -> 0 | F6: ='[1]250 LT ETÜV'!$L$2 -> 23379.89 | G6: 2025-09-04 15:23:18.024 | H6: =K6*1.8*1.4 -> 0 | I6: 1500 | J6: 1500
A7: LT-G0203/H | B7: Belli Değil | C7: Laboratuar Etüvü, 250 litre kapasiteli, ortam sıcaklığı ile 300°C ±2°C arasında, PID dijital kontrol sistemli, Güvenlik termostatlı, Dahili Hava Sirkülasyon Sistemli, İç Yüzey Yapısı : Paslanmaz Çelik İç Hazne, Dış Yüzey Yapısı : Elektrostatik Toz Boyalı Çelik, 3 adet ayarlanabilir raf ile birlikte verilmektedir. 220 V, 50-60 Hz, 1 ph | D7: Laboratory oven, 250 L capacity, ambient to 300°C ±2°C, PID digital control system, equipped of a dual safety thermostat, fan circulated, stainless steel interior, electrostatic painted exterior, 3 adjustable shelves. 220 V, 50-60 Hz, 1 ph | E7: =H7*1.8*1.4 -> 0 | F7: ='[1]250 LT ETÜV'!$L$2 -> 23379.89 | G7: 2025-09-04 15:23:18.025 | H7: =K7*1.8*1.4 -> 0 | I7: 1562 | J7: 1550
A8: LT-G0204 | B8: Belli Değil | C8: Laboratuar Etüvü, 500 litre kapasiteli, ortam sıcaklığı ile 200°C ±2°C arasında, PID dijital kontrol sistemli, Güvenlik termostatlı, Dahili Hava Sirkülasyon Sistemli, İç Yüzey Yapısı : Paslanmaz Çelik İç Hazne, Dış Yüzey Yapısı : Elektrostatik Toz Boyalı Çelik, 4 adet ayarlanabilir raf ile birlikte verilmektedir. 380 V, 50-60 Hz, 3 ph | D8: Laboratory oven, 500 L capacity, ambient to 200°C ±2°C, PID digital control system, equipped of a dual safety thermostat, fan circulated, stainless steel interior, electrostatic painted exterior, 4 adjustable shelves. 380 V, 50-60 Hz, 3 ph | E8: =H8*1.8*1.4 -> 0 | F8: ='[1]500 LT ETÜV'!$L$2 -> 35220.5 | G8: 2025-09-04 15:23:18.026 | H8: =K8*1.8*1.4 -> 0 | I8: 2062 | J8: 1812
A9: LT-G0204/H | B9: Belli Değil | C9: Laboratuar Etüvü, 500 litre kapasiteli, ortam sıcaklığı ile 300°C ±2°C arasında, PID dijital kontrol sistemli, Güvenlik termostatlı, Dahili Hava Sirkülasyon Sistemli, İç Yüzey Yapısı : Paslanmaz Çelik İç Hazne, Dış Yüzey Yapısı : Elektrostatik Toz Boyalı Çelik, 4 adet ayarlanabilir raf ile birlikte verilmektedir. 380 V, 50-60 Hz, 3 ph | D9: Laboratory oven, 500 L capacity, ambient to 300°C ±2°C, PID digital control system, equipped of a dual safety thermostat, fan circulated, stainless steel interior, electrostatic painted exterior, 4 adjustable shelves. 380 V, 50-60 Hz, 3 ph | E9: =H9*1.8*1.4 -> 0 | F9: ='[1]500 LT ETÜV'!$L$2 -> 35220.5 | G9: 2025-09-04 15:23:18.027 | H9: =K9*1.8*1.4 -> 0 | I9: 2312 | J9: 1944
A10: LT-G0205 | B10: Belli Değil | C10: Laboratuar Etüvü, 700 litre kapasiteli, ortam sıcaklığı ile 200°C ±2°C arasında, PID dijital kontrol sistemli, Güvenlik termostatlı, Dahili Hava Sirkülasyon Sistemli, İç Yüzey Yapısı : Paslanmaz Çelik İç Hazne, Dış Yüzey Yapısı : Elektrostatik Toz Boyalı Çelik, 4 adet ayarlanabilir raf ile birlikte verilmektedir. 380 V, 50-60 Hz, 3 ph | D10: Laboratory oven, 700 L capacity, ambient to 200°C ±2°C, PID digital control system, equipped of a dual safety thermostat, fan circulated, stainless steel interior, electrostatic painted exterior, 4 adjustable shelves. 380 V, 50-60 Hz, 3 ph | E10: =H10*1.8*1.4 -> 0 | F10: 59000 | G10: 2025-09-04 15:23:18.028 | H10: =K10*1.8*1.4 -> 0 | I10: 2375 | J10: 2166
A11: LT-G0205/H | B11: Belli Değil | C11: Laboratuar Etüvü, 700 litre kapasiteli, ortam sıcaklığı ile 300°C ±2°C arasında, PID dijital kontrol sistemli, Güvenlik termostatlı, Dahili Hava Sirkülasyon Sistemli, İç Yüzey Yapısı : Paslanmaz Çelik İç Hazne, Dış Yüzey Yapısı : Elektrostatik Toz Boyalı Çelik, 4 adet ayarlanabilir raf ile birlikte verilmektedir. 380 V, 50-60 Hz, 3 ph | D11: Laboratory oven, 700 L capacity, ambient to 300°C ±2°C, PID digital control system, equipped of a dual safety thermostat, fan circulated, stainless steel interior, electrostatic painted exterior, 4 adjustable shelves. 380 V, 50-60 Hz, 3 ph | E11: =H11*1.8*1.4 -> 0 | F11: 59000 | G11: 2025-09-04 15:23:18.029 | H11: =K11*1.8*1.4 -> 0 | I11: 2450 | J11: 2361
A12: LT-G0206 | B12: Belli Değil | C12: Laboratuar Etüvü, 1000 litre kapasiteli, ortam sıcaklığı ile 200°C ±2°C arasında, PID dijital kontrol sistemli, Güvenlik termostatlı, Dahili Hava Sirkülasyon Sistemli, İç Yüzey Yapısı : Paslanmaz Çelik İç Hazne, Dış Yüzey Yapısı : Elektrostatik Toz Boyalı Çelik, 5 adet ayarlanabilir raf ile birlikte verilmektedir. 380 V, 50-60 Hz, 3 ph | D12: Laboratory oven, 1000 L capacity, ambient to 200°C ±2°C, PID digital control system, equipped of a dual safety thermostat, fan circulated, stainless steel interior, electrostatic painted exterior, 4 adjustable shelves. 380 V, 50-60 Hz, 3 ph | E12: =H12*1.8*1.4 -> 0 | F12: 64000 | G12: 2025-09-04 15:23:18.030 | H12: =K12*1.8*1.4 -> 0 | I12: 4250 | J12: 4100
A13: LT-G4600 | B13: Belli Değil | C13: Laboratuar Etüvü, 4600 litre kapasiteli, ortam sıcaklığı ile 200°C ±2°C arasında, PID dijital kontrol sistemli, Güvenlik termostatlı, Dahili Hava Sirkülasyon Sistemli, İç Yüzey Yapısı : Paslanmaz Çelik İç Hazne, Dış Yüzey Yapısı : Elektrostatik Toz Boyalı Çelik, 2 adet etüv arabası ile birlikte verilmektedir. 380 V, 50-60 Hz, 3 ph | D13: Laboratory oven, 4600 L capacity, ambient to 200°C ±2°C, PID digital control system, equipped of a dual safety thermostat, fan circulated, stainless steel interior, electrostatic painted exterior, 2 trolley. 380 V, 50-60 Hz, 3 ph | E13: =H13*1.8*1.4 -> 0 | F13: 88000 | G13: 2025-09-04 15:23:18.031 | H13: =K13*1.8*1.4 -> 0 | I13: 4250 | J13: 4100
A14: LT-G0207 | B14: Belli Değil | C14: Etüv Resiztans | D14: Resistance | E14: 750 | F14: 200 | G14: 2025-09-04 15:23:18.032 | H14: 750 | I14: 22 | J14: 21
A15: LT-G0208 | B15: Belli Değil | C15: Etüv Fan Motoru | D15: Laboratory oven Fan | E15: =H15*1.8*1.4*39 -> 0 | F15: 300 | G15: 2025-09-04 15:23:18.033 | H15: =K15*1.8*1.4*39 -> 0 | I15: 15 | J15: 14
A16: LT-G0275 | B16: Belli Değil | C16: Kül Fırını; Kullanılır hacim: 4 litre Sıcaklık Çalısma Aralığı : 1100 ºC Kontrol Sistemi : PID & MP Sıcaklık Hassasiyeti : ± 2 ºC İç yüzey Yapısı : Fiber Plaka ve Ates Tuğlası Dış Yüzey Yapısı : Elektrostatik Toz Boyalı Çelik 220 V, 50-60 Hz, 1 ph | D16: Muffle furnace, Capacity: 4 L, Max. Temperature: 1100°C Control System: PID & MP, Temperature Sensitivity: ± 2 ºC Internal Surface Material: Fiber plate and Fire Brick, Ext. Surface Material: Steel with Electrostatic Powder Paint 220 V, 50-60 Hz, 1 ph | E16: =H16*1.8*1.4 -> 0 | F16: 53130 | G16: 2025-09-04 15:23:18.034 | H16: =K16*1.8*1.4 -> 0 | I16: 2010 | J16: =X16 -> 0
A17: LT-G0276 | B17: Belli Değil | C17: Kül Fırını; Kullanılır hacim: 7 litre Sıcaklık Çalısma Aralığı : 1100 ºC Kontrol Sistemi : PID & MP Sıcaklık Hassasiyeti : ± 2 ºC İç yüzey Yapısı : Fiber Plaka ve Ates Tuğlası Dış Yüzey Yapısı : Elektrostatik Toz Boyalı Çelik 220 V, 50-60 Hz, 1 ph | D17: Muffle furnace, Capacity: 7 L, Max. Temperature: 1100°C Control System: PID & MP, Temperature Sensitivity: ± 2 ºC Internal Surface Material: Fiber plate and Fire Brick, Ext. Surface Material: Steel with Electrostatic Powder Paint 220 V, 50-60 Hz, 1 ph | E17: =H17*1.8*1.4 -> 0 | F17: 66000 | G17: 2025-09-04 15:23:18.035 | H17: =K17*1.8*1.4 -> 0 | I17: 2310 | J17: =X17 -> 0
A18: LT-G0277 | B18: Belli Değil | C18: Kül Fırını; Kullanılır hacim: 10 litre Sıcaklık Çalısma Aralığı : 1100 ºC Kontrol Sistemi : PID & MP Sıcaklık Hassasiyeti : ± 2 ºC İç yüzey Yapısı : Fiber Plaka ve Ates Tuğlası Dış Yüzey Yapısı : Elektrostatik Toz Boyalı Çelik 380 V, 50-60 Hz, 3 ph | D18: Muffle furnace, Capacity: 10 L, Max. Temperature: 1100°C Control System: PID & MP, Temperature Sensitivity: ± 2 ºC Internal Surface Material: Fiber plate and Fire Brick, Ext. Surface Material: Steel with Electrostatic Powder Paint 380 V, 50-60 Hz, 3 ph | E18: =H18*1.8*1.4 -> 0 | F18: 80000 | G18: 2025-09-04 15:23:18.036 | H18: =K18*1.8*1.4 -> 0 | I18: 3195 | J18: =X18 -> 0
A19: LT-G0278 | B19: Belli Değil | C19: Kül Fırını; Kullanılır hacim: 20 litre Sıcaklık Çalısma Aralığı : 1100 ºC Kontrol Sistemi : PID & MP Sıcaklık Hassasiyeti : ± 2 ºC İç yüzey Yapısı : Fiber Plaka ve Ates Tuğlası Dış Yüzey Yapısı : Elektrostatik Toz Boyalı Çelik 380 V, 50-60 Hz, 3 ph | D19: Muffle furnace, Capacity: 20 L, Max. Temperature: 1100°C Control System: PID & MP, Temperature Sensitivity: ± 2 ºC Internal Surface Material: Fiber plate and Fire Brick, Ext. Surface Material: Steel with Electrostatic Powder Paint 380 V, 50-60 Hz, 3 ph | E19: =H19*1.8*1.4 -> 0 | F19: 96600 | G19: 2025-09-04 15:23:18.037 | H19: =K19*1.8*1.4 -> 0 | I19: =W19 -> 0 | J19: =X19 -> 0
A20: LT-G0283 | B20: Belli Değil | C20: Kül Fırını; Kullanılır hacim: 45 litre Sıcaklık Çalısma Aralığı : 1100 ºC Kontrol Sistemi : PID & MP Sıcaklık Hassasiyeti : ± 2 ºC İç yüzey Yapısı : Fiber Plaka ve Ates Tuğlası Dış Yüzey Yapısı : Elektrostatik Toz Boyalı Çelik 380 V, 50-60 Hz, 3 ph | D20: Muffle furnace, Capacity: 45 L, Max. Temperature: 1100°C Control System: PID & MP, Temperature Sensitivity: ± 2 ºC Internal Surface Material: Fiber plate and Fire Brick, Ext. Surface Material: Steel with Electrostatic Powder Paint 380 V, 50-60 Hz, 3 ph | E20: =H20*1.8*1.4 -> 0 | F20: 140000 | G20: 2025-09-04 15:23:18.038 | H20: =K20*1.8*1.4 -> 0 | I20: =W20 -> 0 | J20: =X20 -> 0
A21: LT-G0279 | B21: Belli Değil | C21: Kül Fırını; Kullanılır hacim: 4 litre Sıcaklık Çalısma Aralığı : 1200 ºC Kontrol Sistemi : PID & MP Sıcaklık Hassasiyeti : ± 2 ºC İç yüzey Yapısı : Fiber Plaka ve Ates Tuğlası Dış Yüzey Yapısı : Elektrostatik Toz Boyalı Çelik 220 V, 50-60 Hz, 1 ph | D21: Muffle furnace, Capacity: 4 L, Max. Temperature: 1200°C Control System: PID & MP, Temperature Sensitivity: ± 2 ºC Internal Surface Material: Fiber plate and Fire Brick, Ext. Surface Material: Steel with Electrostatic Powder Paint 220 V, 50-60 Hz, 1 ph | E21: =H21*1.8*1.4 -> 0 | F21: 53130 | G21: 2025-09-04 15:23:18.039 | H21: =K21*1.8*1.4 -> 0 | I21: 2490 | J21: =X21 -> 0
A22: LT-G0280 | B22: Belli Değil | C22: Kül Fırını; Kullanılır hacim: 7 litre Sıcaklık Çalısma Aralığı : 1200 ºC Kontrol Sistemi : PID & MP Sıcaklık Hassasiyeti : ± 2 ºC İç yüzey Yapısı : Fiber Plaka ve Ates Tuğlası Dış Yüzey Yapısı : Elektrostatik Toz Boyalı Çelik 220 V, 50-60 Hz, 1 ph | D22: Muffle furnace, Capacity: 7 L, Max. Temperature: 1200°C Control System: PID & MP, Temperature Sensitivity: ± 2 ºC Internal Surface Material: Fiber plate and Fire Brick, Ext. Surface Material: Steel with Electrostatic Powder Paint 220 V, 50-60 Hz, 1 ph | E22: =H22*1.8*1.4 -> 0 | F22: 66000 | G22: 2025-09-04 15:23:18.040 | H22: =K22*1.8*1.4 -> 0 | I22: 2730 | J22: =X22 -> 0
A23: LT-G0281 | B23: Belli Değil | C23: Kül Fırını; Kullanılır hacim: 10 litre Sıcaklık Çalısma Aralığı : 1200 ºC Kontrol Sistemi : PID & MP Sıcaklık Hassasiyeti : ± 2 ºC İç yüzey Yapısı : Fiber Plaka ve Ates Tuğlası Dış Yüzey Yapısı : Elektrostatik Toz Boyalı Çelik 220 V, 50-60 Hz, 1 ph | D23: Muffle furnace, Capacity: 10 L, Max. Temperature: 1200°C Control System: PID & MP, Temperature Sensitivity: ± 2 ºC Internal Surface Material: Fiber plate and Fire Brick, Ext. Surface Material: Steel with Electrostatic Powder Paint 220 V, 50-60 Hz, 1 ph | E23: =H23*1.8*1.4 -> 0 | F23: 80000 | G23: 2025-09-04 15:23:18.041 | H23: =K23*1.8*1.4 -> 0 | I23: 2730 | J23: =X23 -> 0
A24: LT-G0282 | B24: Belli Değil | C24: Kül Fırını; Kullanılır hacim: 20 litre Sıcaklık Çalısma Aralığı : 1200 ºC Kontrol Sistemi : PID & MP Sıcaklık Hassasiyeti : ± 2 ºC İç yüzey Yapısı : Fiber Plaka ve Ates Tuğlası Dış Yüzey Yapısı : Elektrostatik Toz Boyalı Çelik 220 V, 50-60 Hz, 1 ph | D24: Muffle furnace, Capacity: 20 L, Max. Temperature: 1200°C Control System: PID & MP, Temperature Sensitivity: ± 2 ºC Internal Surface Material: Fiber plate and Fire Brick, Ext. Surface Material: Steel with Electrostatic Powder Paint 220 V, 50-60 Hz, 1 ph | E24: =H24*1.8*1.4 -> 0 | F24: 96600 | G24: 2025-09-04 15:23:18.042 | H24: =K24*1.8*1.4 -> 0 | I24: 2730 | J24: =X24 -> 0
A25: LT-G0284 | B25: Belli Değil | C25: Kül Fırını; Kullanılır hacim: 45 litre Sıcaklık Çalısma Aralığı : 1200 ºC Kontrol Sistemi : PID & MP Sıcaklık Hassasiyeti : ± 2 ºC İç yüzey Yapısı : Fiber Plaka ve Ates Tuğlası Dış Yüzey Yapısı : Elektrostatik Toz Boyalı Çelik 380 V, 50-60 Hz, 3 ph | D25: Muffle furnace, Capacity: 45 L, Max. Temperature: 1200°C Control System: PID & MP, Temperature Sensitivity: ± 2 ºC Internal Surface Material: Fiber plate and Fire Brick, Ext. Surface Material: Steel with Electrostatic Powder Paint 380 V, 50-60 Hz, 3 ph | E25: =H25*1.8*1.4 -> 0 | F25: 140000 | G25: 2025-09-04 15:23:18.043 | H25: =K25*1.8*1.4 -> 0 | I25: =W25 -> 0 | J25: =X25 -> 0
A26: LT-G0241 | B26: Belli Değil | C26: Dijital Elektrikli Ocak– Hot Plate Dış Yüzey Ölçüleri : 30x30 Sıcaklık Çalışma Aralığı : Ortam sıcaklıgı ile 350°C Kontrol Sistemi : PID Dijital Termostat Sıcaklık Hassasiyeti : ± 2 ºC Isıtma Tablası : Döküm / Kumlama Sac Dış Yüzey Yapısı : Elektrostatik Toz Boyalı Çelik Güç Değerleri : 220 V, 50 Hz, 1 ph | D26: Digital Electrical Hot Plate Dimensions : 30x30 Temperature Range is ambient to 350°C. Controller System : PID Digital Thermostat Heater Table made from Cast / Sand Blasting Sheet Iron. Power Supply : 220 V, 50 Hz, 1 ph | E26: =H26*1.8*1.4 -> 0 | F26: 9500 | G26: 2025-09-04 15:23:18.044 | H26: =K26*1.8*1.4 -> 0 | I26: 591 | J26: 550
A27: LT-G0242 | B27: Belli Değil | C27: Dijital Elektrikli Ocak– Hot Plate Dış Yüzey Ölçüleri : 30x60 Sıcaklık Çalışma Aralığı : Ortam sıcaklıgı ile 350°C Kontrol Sistemi : PID Dijital Termostat Sıcaklık Hassasiyeti : ± 2 ºC Isıtma Tablası : Döküm / Kumlama Sac Dış Yüzey Yapısı : Elektrostatik Toz Boyalı Çelik Güç Değerleri : 220 V, 50 Hz, 1 ph | D27: Digital Electrical Hot Plate Dimensions : 30x60 Temperature Range is ambient to 350°C. Controller System : PID Digital Thermostat Heater Table made from Cast / Sand Blasting Sheet Iron. Power Supply : 220 V, 50 Hz, 1 ph | E27: =H27*1.8*1.4 -> 0 | F27: 0 | G27: 2025-09-04 15:23:18.045 | H27: =K27*1.8*1.4 -> 0 | I27: 591 | J27: 550
A28: LT-G0243 | B28: Belli Değil | C28: Dijital Elektrikli Ocak– Hot Plate Dış Yüzey Ölçüleri : 40x40 Sıcaklık Çalışma Aralığı : Ortam sıcaklıgı ile 350°C Kontrol Sistemi : PID Dijital Termostat Sıcaklık Hassasiyeti : ± 2 ºC Isıtma Tablası : Döküm / Kumlama Sac Dış Yüzey Yapısı : Elektrostatik Toz Boyalı Çelik Güç Değerleri : 220 V, 50 Hz, 1 ph | D28: Digital Electrical Hot Plate Dimensions : 40x40 Temperature Range is ambient to 350°C. Controller System : PID Digital Thermostat Heater Table made from Cast / Sand Blasting Sheet Iron. Power Supply : 220 V, 50 Hz, 1 ph | E28: =H28*1.8*1.4 -> 0 | F28: 10000 | G28: 2025-09-04 15:23:18.046 | H28: =K28*1.8*1.4 -> 0 | I28: 711 | J28: 740
A29: LT-G0244 | B29: Belli Değil | C29: Tekli Elektrikli Ocak, 1500 Watt, Analog Termostatlı | D29: Single Hot Plate. 1500 Watt. Analog Thermostat. | E29: =H29*1.8*1.4 -> 0 | F29: 800 | G29: 2025-09-04 15:23:18.047 | H29: =K29*1.8*1.4 -> 0 | I29: 72 | J29: =X29 -> 0
A30: LT-G0245 | B30: Belli Değil | C30: Çift Gözlü Elektrikli Ocak, 1000+1500 Watt, Analog Termostatlı | D30: Double Hot Plate. 1000+1500 Watt. Analog Thermostat. | E30: =H30*1.8*1.4 -> 0 | F30: 1800 | G30: 2025-09-04 15:23:18.048 | H30: =K30*1.8*1.4 -> 0 | I30: 84 | J30: =X30 -> 0
A31: LT-G0246 | B31: Belli Değil | C31: Analog Isıtıcılı Manyetik Karıştırıcı. 380°C'ye kadar ısıtma özelliği, 80-1500 devir/dakika hız. 20 litre karıştırma kapasiteli, Hız ve Sıcaklık Ayarı Analog. Seramik kaplı tabla, 190 x 190 mm tabla boyutu, , 600 W, 2 adet manyetik balık ile birlikte. | D31: Analog Hot plate with magnetic stirrer, ambient to 380 °C temperature range, 80-1500 rpm stirring speed, 20 lt stirring capacity, Ceramic table, 180x180 mm hot plate. 220-240V, 50-60Hz, 1ph | E31: =H31*1.8*1.4 -> 0 | F31: 12000 | G31: 2025-09-04 15:23:18.049 | H31: =K31*1.8*1.4 -> 0 | I31: 720 | J31: =X31 -> 0
A32: LT-G0247 | B32: Belli Değil | C32: Dijital Isıtıcılı Manyetik Karıştırıcı. 380°C'ye kadar ısıtma özelliği, 80-1500 devir/dakika hız. 20 litre karıştırma kapasiteli, Hız ve Sıcaklık Ayarı Analog. Seramik kaplı tabla, 190 x 190 mm tabla boyutu, , 600 W, 2 adet manyetik balık ile birlikte. | D32: Digital Hot plate with magnetic stirrer, ambient to 380 °C temperature range, 80-1500 rpm stirring speed, 20 lt stirring capacity, Ceramic table, 180x180 mm hot plate. 220-240V, 50-60Hz, 1ph | E32: =H32*1.8*1.4 -> 0 | F32: 16000 | G32: 2025-09-04 15:23:18.050 | H32: =K32*1.8*1.4 -> 0 | I32: 900 | J32: =X32 -> 0
A33: LT-G0248 | B33: Belli Değil | C33: ÇEKER OCAK | D33: Fume Hood | E33: =H33*1.8*1.4 -> 0 | F33: 80000 | G33: 2025-09-04 15:23:18.051 | H33: =K33*1.8*1.4 -> 0 | I33: 7500
A34: LT-G0250 | B34: Belli Değil | C34: Kurutma Makinası, 220 V, 50-60 Hz, 1 ph | D34: Warm-Air Drier, 220 V, 50-60 Hz, 1 ph | E34: =H34*1.8*1.4 -> 0 | F34: 600 | G34: 2025-09-04 15:23:18.052 | H34: =K34*1.8*1.4 -> 0 | I34: 78 | J34: =X34 -> 0
A35: LT-G0255 | B35: Belli Değil | C35: Sıcak Hava Tabancası, 250/500 lt/dak - 350/550°C 230 V, 50-60 Hz, 1 ph | D35: Hot Air Gun, 250/500 L/min - 350/550°C . 220 V, 50-60 Hz, 1 ph | E35: =H35*1.8*1.4 -> 0 | F35: 2000 | G35: 2025-09-04 15:23:18.053 | H35: =K35*1.8*1.4 -> 0 | I35: 111 | J35: =X35 -> 0
A36: LT-G0260 | B36: Belli Değil | C36: Mikrodalga Fırın, 17 L kapasiteli, max 250 °C, 100 dakikaya ayarlanabilir mekanik program saati, döner cam tepsi ve döner destek aparatı. 220 V, 50-60 Hz, 1 ph | D36: Microwave Oven, 17 L capacity, max 250 °C, 100 min program timer, turntable system, 220 V, 50-60 Hz, 1 ph | E36: =H36*1.8*1.4 -> 0 | F36: 2700 | G36: 2025-09-04 15:23:18.054 | H36: =K36*1.8*1.4 -> 0 | I36: 192 | J36: =X36 -> 0
A37: LT-A0072 | B37: Belli Değil | C37: Hızlı Nem Tayin Cihazı(Speedy Moisture Test), Arazi koşullarında toz, karışım ve hamur haldeki toprak, kum, kil, agrega ve diğer granüler malzemelerin nem içeriklerini hızlı ve doğru tespit eder. Kapasite: 20 gr. Hassas Terazisi, ölçüm kaşığı ve kabı, 1 kutu kalsiyum karpit tepkileyici, temizleme fırçası, ahşap muhafazası ile birlikte set olarak verilmektedir. | D37: Speedy Moisture Test, used to determine moisture content in soils, sand and fine aggregates. 20 gr sample can be used. Precision Scale, measuring spoons and cups, 1 box of calcium carbide reagent, cleaning brush, wooden enclosure wit a complete set as. | E37: =H37*1.8*1.4 -> 0 | F37: 1200 | G37: 2025-09-04 15:23:18.055 | H37: =K37*1.8*1.4 -> 0 | I37: 1250 | J37: =X37 -> 0
A38: LT-G0097 | B38: Belli Değil | C38: Desikatör; 210 mm çapında | D38: Non-Vacuum Dessicator Ø 210 mm | E38: =H38*1.8*1.4 -> 0 | F38: =46.26*42.3 -> 1956.798 | G38: 2025-09-04 15:23:18.056 | H38: =K38*1.8*1.4 -> 0 | I38: 90 | J38: =X38 -> 0
A39: LT-G0098 | B39: Belli Değil | C39: Desikatör; 240 mm çapında | D39: Non-Vacuum Dessicator Ø 240 mm | E39: =H39*1.8*1.4 -> 0 | F39: =58.65*42.3 -> 2480.895 | G39: 2025-09-04 15:23:18.057 | H39: =K39*1.8*1.4 -> 0 | I39: 132 | J39: =X39 -> 0
A40: LT-G0099 | B40: Belli Değil | C40: Desikatör; 300 mm çapında | D40: Non-Vacuum Dessicator Ø 300 mm | E40: =H40*1.8*1.4 -> 0 | F40: =99.24*42.3 -> 4197.852 | G40: 2025-09-04 15:23:18.058 | H40: =K40*1.8*1.4 -> 0 | I40: 180 | J40: =X40 -> 0
...
